Workbook

Sheet Details
A1: Task ID | B1: Date | C1: Section | D1: Task / Description | E1: Cost | F1: Money In | G1: Money In Method | H1: Vendor / Contractor | I1: Payment Method | J1: Status | K1: Cost Type | L1: Planned Start Date | M1: Planned End Date | N1: Actual End Date | O1: Notes
A2: 1 | B2: 19/8/2025 | C2: Site preparation | D2: amakamba | E2: 1200 | G2: Cash | J2: Completed | K2: Material
A3: 2 | B3: 19/8/2025 | C3: Site preparation | D3: imisumari | E3: 3000 | G3: Cash | J3: Completed | K3: Material
A4: 3 | B4: 19/8/2025 | C4: Security | D4: umuzamu | E4: 2000 | G4: Cash | J4: Completed | K4: Manpower
A5: 4 | B5: 19/8/2025 | C5: Transport | D5: ticket | E5: 500 | G5: Cash | J5: Completed | K5: Material
A6: 5 | B6: 19/8/2025 | C6: Site preparation | D6: abayedi | E6: 8000 | G6: Cash | J6: Completed | K6: Manpower
A7: 6 | B7: 19/8/2025 | C7: Site preparation | D7: abafundi | E7: 25000 | G7: Cash | J7: Completed | K7: Manpower
A8: 7 | B8: 20/8/2025 | C8: money | D8: amafaranga | F8: 100000 | G8: Mobile Money | J8: Completed | K8: cash in
A9: 8 | B9: 20/8/2025 | C9: Site preparation | D9: amakamba | E9: 800 | G9: Cash | J9: Completed | K9: Material
A10: 9 | B10: 20/8/2025 | C10: money | D10: kubikuza | E10: 1500 | G10: Cash | J10: Completed | K10: cash out
A11: 10 | B11: 20/8/2025 | C11: Site preparation | D11: abayedi | E11: 15000 | G11: Cash | J11: Completed | K11: Manpower
A12: 11 | B12: 20/8/2025 | C12: Site preparation | D12: abafundi | E12: 20000 | G12: Cash | J12: Completed | K12: Manpower
A13: 12 | B13: 21/8/2025 | C13: Site preparation | D13: abafundi | E13: 15000 | G13: Cash | J13: Completed | K13: Manpower
A14: 13 | B14: 21/8/2025 | C14: Site preparation | D14: abayedi | E14: 30000 | G14: Cash | J14: Completed | K14: Manpower
A15: 14 | B15: 21/8/2025 | C15: money | D15: amafaranga | F15: 200000 | G15: Mobile Money | J15: Completed | K15: cash in
A16: 15 | B16: 22/8/2025 | C16: Site preparation | D16: ingorofani | E16: 9000 | G16: Cash | J16: Completed | K16: Repairing
A17: 16 | B17: 22/8/2025 | C17: Transport | D17: ticket y'ingorofani | E17: 2000 | G17: Cash | J17: Completed | K17: Material
A18: 17 | B18: 22/8/205 | C18: Site preparation | D18: umunyururu | E18: 3000 | G18: Cash | J18: Completed | K18: Material
A19: 18 | B19: 22/8/2025 | C19: Site preparation | D19: ingufuri | E19: 1500 | G19: Cash | J19: Completed | K19: Material
A20: 19 | B20: 22/8/2025 | C20: Site preparation | D20: kubikuza | E20: 2000 | G20: Cash | J20: Completed | K20: cash out
A21: 20 | B21: 22/8/2025 | C21: Site preparation | D21: abayedi | E21: 25000 | G21: Cash | J21: Completed | K21: Manpower
A22: 21 | B22: 22/8/205 | C22: Site preparation | D22: umufundi | E22: 15000 | G22: Cash | J22: Completed | K22: Manpower
A23: 22 | B23: 22/8/2025 | C23: Site preparation | D23: gupatana umucyingo | E23: 150000 | F23: 150000 | G23: Cash | J23: Completed | K23: Manpower
A24: 23 | B24: 23/8/2025 | C24: Site preparation | D24: imbaho | E24: 1000 | G24: Cash | J24: Completed | K24: Material
A25: 24 | B25: 23/8/2025 | C25: money | D25: kubikuza | E25: 1500 | G25: Cash | J25: Completed | K25: cash out
A26: 25 | B26: 23/8/2025 | C26: Site preparation | D26: abayedi | E26: 35000 | G26: Cash | J26: Completed | K26: Manpower
A27: 26 | B27: 23/8/2025 | C27: Site preparation | D27: umufundi | E27: 15000 | G27: Cash | J27: Completed | K27: Manpower
A28: 27 | B28: 24/8/2025 | C28: Site preparation | D28: abayedi | E28: 30000 | G28: Cash | J28: Completed | K28: Manpower
A29: 28 | B29: 24/8/2025 | C29: Security | D29: umuzamu | E29: 3000 | G29: Cash | J29: Completed | K29: Manpower
A30: 29 | B30: 26/8/2025 | C30: Site preparation | D30: imbaho | E30: 7600 | G30: Cash | J30: Completed | K30: Material
A31: 30 | B31: 26/8/2025 | C31: Site preparation | D31: ikayii | E31: 3000 | G31: Cash | J31: Completed | K31: Material
A32: 31 | B32: 26/8/2025 | C32: money | D32: kubikuza | E32: 1500 | G32: Cash | J32: Completed | K32: cash out
A33: 32 | B33: 26/8/2025 | C33: Site preparation | D33: abayedi | E33: 30000 | G33: Cash | J33: Completed | K33: Manpower
A34: 33 | B34: 26/2025 | C34: money | D34: amafaranga | F34: 100000 | G34: Cash | J34: Completed | K34: cash in
A35: 34 | B35: 26/8/2025 | C35: Site preparation | D35: umufundi | E35: 15000 | G35: Cash | J35: Completed | K35: Manpower
A36: 35 | B36: 28/8/2025 | C36: Site preparation | D36: amafaranga | F36: 150000 | G36: Cash | J36: Completed | K36: cash in
A37: 36 | B37: 28/8/2025 | C37: Site preparation | D37: gupatana toilet | E37: 22200 | G37: Cash | J37: Completed | K37: Manpower
A38: 37 | B38: 28/8/2025 | C38: Site preparation | D38: gupakurura | E38: 6000 | G38: Cash | J38: Completed | K38: Manpower
A39: 38 | B39: 28/8/2025 | C39: Site preparation | D39: umuzamu | E39: 3000 | G39: Cash | J39: Completed | K39: Manpower
A40: 39 | B40: 28/8/2025 | C40: Site preparation | D40: umuyedi | E40: 5000 | G40: Cash | J40: Completed | K40: Manpower
...

Sheet Overview
A1: Section | B1: Cost | C1: Status | E1: Cost Type | F1: Cost | H1: Date | I1: Money In | J1: Cost | K1: 0
A2: =IF(Settings!A3="","",Settings!A3) -> Land & Permits | B2: =IF($A2="","",SUMIF(Details!$C:$C,$A2,Details!$E:$E)) -> 0 | C2: =IF($A2="","",IF(B2=0,"Not Started",IF(B2<#REF!,"In Progress","Completed"))) -> Not Started | E2: =IF(Settings!D2="","",Settings!D2) -> Material | F2: =IF($E2="","",SUMIF(Details!$K:$K,$E2,Details!$E:$E)) -> 2627200 | I2: =IF(H2="","",Details!$F2) | K2: =IF(H2="","",I2-J2)
A3: =IF(Settings!A4="","",Settings!A4) -> Foundation | B3: =IF($A3="","",SUMIF(Details!$C:$C,$A3,Details!$E:$E)) -> 1026500 | C3: =IF($A3="","",IF(B3=0,"Not Started",IF(B3<#REF!,"In Progress","Completed"))) -> #REF! | E3: =IF(Settings!D3="","",Settings!D3) -> Manpower | J3: =IF(H3="","",Details!$E3) | K3: =IF(H3="","",K2+I3-J3)
A4: =IF(Settings!A5="","",Settings!A5) -> Structure / Walls | B4: =IF($A4="","",SUMIF(Details!$C:$C,$A4,Details!$E:$E)) -> 4928600 | C4: =IF($A4="","",IF(B4=0,"Not Started",IF(B4<#REF!,"In Progress","Completed"))) -> #REF! | E4: =IF(Settings!D4="","",Settings!D4) -> Other | F4: =IF($E4="","",SUMIF(Details!$K:$K,$E4,Details!$E:$E)) -> 0 | H4: =IF(Details!$B4="","",Details!$B4) -> 19/8/2025 | I4: =IF(H4="","",Details!$F4) | J4: =IF(H4="","",Details!$E4) -> 2000 | K4: =IF(H4="","",K3+I4-J4) -> -2000
A5: =IF(Settings!A6="","",Settings!A6) -> Roofing | B5: =IF($A5="","",SUMIF(Details!$C:$C,$A5,Details!$E:$E)) -> 0 | C5: =IF($A5="","",IF(B5=0,"Not Started",IF(B5<#REF!,"In Progress","Completed"))) -> Not Started | E5: cash in | F5: =IF($E5="","",SUMIF(Details!$K:$K,$E5,Details!$E:$E)) -> 0 | H5: =IF(Details!$B5="","",Details!$B5) -> 19/8/2025 | I5: =IF(H5="","",Details!$F5) | J5: =IF(H5="","",Details!$E5) -> 500 | K5: =IF(H5="","",K4+I5-J5) -> -2500
A6: =IF(Settings!A7="","",Settings!A7) -> Doors & Windows | B6: =IF($A6="","",SUMIF(Details!$C:$C,$A6,Details!$E:$E)) -> 0 | C6: =IF($A6="","",IF(B6=0,"Not Started",IF(B6<#REF!,"In Progress","Completed"))) -> Not Started | E6: cash out | F6: =IF($E6="","",SUMIF(Details!$K:$K,$E6,Details!$E:$E)) -> 124500 | H6: =IF(Details!$B6="","",Details!$B6) -> 19/8/2025 | I6: =IF(H6="","",Details!$F6) | J6: =IF(H6="","",Details!$E6) -> 8000 | K6: =IF(H6="","",K5+I6-J6) -> -10500
A7: =IF(Settings!A8="","",Settings!A8) -> Electrical | B7: =IF($A7="","",SUMIF(Details!$C:$C,$A7,Details!$E:$E)) -> 2000 | C7: =IF($A7="","",IF(B7=0,"Not Started",IF(B7<#REF!,"In Progress","Completed"))) -> #REF! | E7: =IF(Settings!D7="","",Settings!D7) -> Repairing | F7: =IF($E7="","",SUMIF(Details!$K:$K,$E7,Details!$E:$E)) -> 26000 | H7: =IF(Details!$B7="","",Details!$B7) -> 19/8/2025 | I7: =IF(H7="","",Details!$F7) | J7: =IF(H7="","",Details!$E7) -> 25000 | K7: =IF(H7="","",K6+I7-J7) -> -35500
A8: =IF(Settings!A9="","",Settings!A9) -> Plumbing | B8: =IF($A8="","",SUMIF(Details!$C:$C,$A8,Details!$E:$E)) -> 0 | C8: =IF($A8="","",IF(B8=0,"Not Started",IF(B8<#REF!,"In Progress","Completed"))) -> Not Started | H8: =IF(Details!$B8="","",Details!$B8) -> 20/8/2025 | I8: =IF(H8="","",Details!$F8) -> 100000 | J8: =IF(H8="","",Details!$E8) | K8: =IF(H8="","",K7+I8-J8) -> 64500
A9: =IF(Settings!A10="","",Settings!A10) -> Finishes (Interior) | B9: =IF($A9="","",SUMIF(Details!$C:$C,$A9,Details!$E:$E)) -> 0 | C9: =IF($A9="","",IF(B9=0,"Not Started",IF(B9<#REF!,"In Progress","Completed"))) -> Not Started | H9: =IF(Details!$B9="","",Details!$B9) -> 20/8/2025 | I9: =IF(H9="","",Details!$F9) | J9: =IF(H9="","",Details!$E9) -> 800 | K9: =IF(H9="","",K8+I9-J9) -> 63700
A10: =IF(Settings!A11="","",Settings!A11) -> Finishes (Exterior) | B10: =IF($A10="","",SUMIF(Details!$C:$C,$A10,Details!$E:$E)) -> 0 | C10: =IF($A10="","",IF(B10=0,"Not Started",IF(B10<#REF!,"In Progress","Completed"))) -> Not Started | H10: =IF(Details!$B10="","",Details!$B10) -> 20/8/2025 | I10: =IF(H10="","",Details!$F10) | J10: =IF(H10="","",Details!$E10) -> 1500 | K10: =IF(H10="","",K9+I10-J10) -> 62200
A11: =IF(Settings!A12="","",Settings!A12) -> Landscaping | B11: =IF($A11="","",SUMIF(Details!$C:$C,$A11,Details!$E:$E)) -> 0 | C11: =IF($A11="","",IF(B11=0,"Not Started",IF(B11<#REF!,"In Progress","Completed"))) -> Not Started | H11: =IF(Details!$B11="","",Details!$B11) -> 20/8/2025 | I11: =IF(H11="","",Details!$F11) | J11: =IF(H11="","",Details!$E11) -> 15000 | K11: =IF(H11="","",K10+I11-J11) -> 47200
A12: =IF(Settings!A13="","",Settings!A13) -> Contingency | B12: =IF($A12="","",SUMIF(Details!$C:$C,$A12,Details!$E:$E)) -> 0 | C12: =IF($A12="","",IF(B12=0,"Not Started",IF(B12<#REF!,"In Progress","Completed"))) -> Not Started | H12: =IF(Details!$B12="","",Details!$B12) -> 20/8/2025 | I12: =IF(H12="","",Details!$F12) | J12: =IF(H12="","",Details!$E12) -> 20000 | K12: =IF(H12="","",K11+I12-J12) -> 27200
A13: =IF(Settings!A14="","",Settings!A14) -> Security | B13: =IF($A13="","",SUMIF(Details!$C:$C,$A13,Details!$E:$E)) -> 135500 | C13: =IF($A13="","",IF(B13=0,"Not Started",IF(B13<#REF!,"In Progress","Completed"))) -> #REF! | H13: =IF(Details!$B13="","",Details!$B13) -> 21/8/2025 | I13: =IF(H13="","",Details!$F13) | J13: =IF(H13="","",Details!$E13) -> 15000 | K13: =IF(H13="","",K12+I13-J13) -> 12200
A14: money | B14: =IF($A14="","",SUMIF(Details!$C:$C,$A14,Details!$E:$E)) -> 77000 | C14: =IF($A14="","",IF(B14=0,"Not Started",IF(B14<#REF!,"In Progress","Completed"))) -> #REF! | H14: =IF(Details!$B15="","",Details!$B15) -> 21/8/2025 | I14: =IF(H14="","",Details!$F15) -> 200000 | J14: =IF(H14="","",Details!$E15) | K14: =IF(H14="","",#REF!+I14-J14) -> #REF!
A15: Transport | B15: =IF($A15="","",SUMIF(Details!$C:$C,$A15,Details!$E:$E)) -> 330500 | C15: =IF($A15="","",IF(B15=0,"Not Started",IF(B15<#REF!,"In Progress","Completed"))) -> #REF! | H15: =IF(Details!$B16="","",Details!$B16) -> 22/8/2025 | I15: =IF(H15="","",Details!$F16) | J15: =IF(H15="","",Details!$E16) -> 9000 | K15: =IF(H15="","",K14+I15-J15) -> #REF!
A16: withdrwal | B16: =IF($A16="","",SUMIF(Details!$C:$C,$A16,Details!$E:$E)) -> 0 | C16: =IF($A16="","",IF(B16=0,"Not Started",IF(B16<#REF!,"In Progress","Completed"))) -> Not Started | H16: =IF(Details!$B17="","",Details!$B17) -> 22/8/2025 | I16: =IF(H16="","",Details!$F17) | J16: =IF(H16="","",Details!$E17) -> 2000 | K16: =IF(H16="","",K15+I16-J16) -> #REF!
A17: =IF(Settings!A18="","",Settings!A18) | B17: =IF($A17="","",SUMIF(Details!$C:$C,$A17,Details!$E:$E)) | C17: =IF($A17="","",IF(B17=0,"Not Started",IF(B17<#REF!,"In Progress","Completed"))) | H17: =IF(Details!$B18="","",Details!$B18) -> 22/8/205 | I17: =IF(H17="","",Details!$F18) | J17: =IF(H17="","",Details!$E18) -> 3000 | K17: =IF(H17="","",K16+I17-J17) -> #REF!
A18: =IF(Settings!A19="","",Settings!A19) | B18: =IF($A18="","",SUMIF(Details!$C:$C,$A18,Details!$E:$E)) | C18: =IF($A18="","",IF(B18=0,"Not Started",IF(B18<#REF!,"In Progress","Completed"))) | H18: =IF(Details!$B19="","",Details!$B19) -> 22/8/2025 | I18: =IF(H18="","",Details!$F19) | J18: =IF(H18="","",Details!$E19) -> 1500 | K18: =IF(H18="","",K17+I18-J18) -> #REF!
A19: =IF(Settings!A20="","",Settings!A20) | B19: =IF($A19="","",SUMIF(Details!$C:$C,$A19,Details!$E:$E)) | C19: =IF($A19="","",IF(B19=0,"Not Started",IF(B19<#REF!,"In Progress","Completed"))) | H19: =IF(Details!$B20="","",Details!$B20) -> 22/8/2025 | I19: =IF(H19="","",Details!$F20) | J19: =IF(H19="","",Details!$E20) -> 2000 | K19: =IF(H19="","",K18+I19-J19) -> #REF!
A20: =IF(Settings!A21="","",Settings!A21) | B20: =IF($A20="","",SUMIF(Details!$C:$C,$A20,Details!$E:$E)) | C20: =IF($A20="","",IF(B20=0,"Not Started",IF(B20<#REF!,"In Progress","Completed"))) | H20: =IF(Details!$B21="","",Details!$B21) -> 22/8/2025 | I20: =IF(H20="","",Details!$F21) | J20: =IF(H20="","",Details!$E21) -> 25000 | K20: =IF(H20="","",K19+I20-J20) -> #REF!
A21: =IF(Settings!A22="","",Settings!A22) | B21: =IF($A21="","",SUMIF(Details!$C:$C,$A21,Details!$E:$E)) | C21: =IF($A21="","",IF(B21=0,"Not Started",IF(B21<#REF!,"In Progress","Completed"))) | H21: =IF(Details!$B22="","",Details!$B22) -> 22/8/205 | I21: =IF(H21="","",Details!$F22) | J21: =IF(H21="","",Details!$E22) -> 15000 | K21: =IF(H21="","",K20+I21-J21) -> #REF!
A22: =IF(Settings!A23="","",Settings!A23) | B22: =IF($A22="","",SUMIF(Details!$C:$C,$A22,Details!$E:$E)) | C22: =IF($A22="","",IF(B22=0,"Not Started",IF(B22<#REF!,"In Progress","Completed"))) | H22: =IF(Details!$B23="","",Details!$B23) -> 22/8/2025 | I22: =IF(H22="","",Details!$F23) -> 150000 | J22: =IF(H22="","",Details!$E23) -> 150000 | K22: =IF(H22="","",K21+I22-J22) -> #REF!
A23: =IF(Settings!A24="","",Settings!A24) | B23: =IF($A23="","",SUMIF(Details!$C:$C,$A23,Details!$E:$E)) | C23: =IF($A23="","",IF(B23=0,"Not Started",IF(B23<#REF!,"In Progress","Completed"))) | H23: =IF(Details!$B24="","",Details!$B24) -> 23/8/2025 | I23: =IF(H23="","",Details!$F24) | J23: =IF(H23="","",Details!$E24) -> 1000 | K23: =IF(H23="","",K22+I23-J23) -> #REF!
A24: =IF(Settings!A25="","",Settings!A25) | B24: =IF($A24="","",SUMIF(Details!$C:$C,$A24,Details!$E:$E)) | C24: =IF($A24="","",IF(B24=0,"Not Started",IF(B24<#REF!,"In Progress","Completed"))) | H24: =IF(Details!$B25="","",Details!$B25) -> 23/8/2025 | I24: =IF(H24="","",Details!$F25) | J24: =IF(H24="","",Details!$E25) -> 1500 | K24: =IF(H24="","",K23+I24-J24) -> #REF!
A25: =IF(Settings!A26="","",Settings!A26) | B25: =IF($A25="","",SUMIF(Details!$C:$C,$A25,Details!$E:$E)) | C25: =IF($A25="","",IF(B25=0,"Not Started",IF(B25<#REF!,"In Progress","Completed"))) | H25: =IF(Details!$B26="","",Details!$B26) -> 23/8/2025 | I25: =IF(H25="","",Details!$F26) | J25: =IF(H25="","",Details!$E26) -> 35000 | K25: =IF(H25="","",K24+I25-J25) -> #REF!
A26: =IF(Settings!A27="","",Settings!A27) | B26: =IF($A26="","",SUMIF(Details!$C:$C,$A26,Details!$E:$E)) | C26: =IF($A26="","",IF(B26=0,"Not Started",IF(B26<#REF!,"In Progress","Completed"))) | H26: =IF(Details!$B27="","",Details!$B27) -> 23/8/2025 | I26: =IF(H26="","",Details!$F27) | J26: =IF(H26="","",Details!$E27) -> 15000 | K26: =IF(H26="","",K25+I26-J26) -> #REF!
A27: =IF(Settings!A28="","",Settings!A28) | B27: =IF($A27="","",SUMIF(Details!$C:$C,$A27,Details!$E:$E)) | C27: =IF($A27="","",IF(B27=0,"Not Started",IF(B27<#REF!,"In Progress","Completed"))) | H27: =IF(Details!$B28="","",Details!$B28) -> 24/8/2025 | I27: =IF(H27="","",Details!$F28) | J27: =IF(H27="","",Details!$E28) -> 30000 | K27: =IF(H27="","",K26+I27-J27) -> #REF!
A28: =IF(Settings!A29="","",Settings!A29) | B28: =IF($A28="","",SUMIF(Details!$C:$C,$A28,Details!$E:$E)) | C28: =IF($A28="","",IF(B28=0,"Not Started",IF(B28<#REF!,"In Progress","Completed"))) | H28: =IF(Details!$B29="","",Details!$B29) -> 24/8/2025 | I28: =IF(H28="","",Details!$F29) | J28: =IF(H28="","",Details!$E29) -> 3000 | K28: =IF(H28="","",K27+I28-J28) -> #REF!
... A32: =IF(Settings!A33="","",Settings!A33) | B32: =IF($A32="","",SUMIF(Details!$C:$C,$A32,Details!$E:$E)) | C32: =IF($A32="","",IF(B32=0,"Not Started",IF(B32<#REF!,"In Progress","Completed"))) | H32: =IF(Details!$B33="","",Details!$B33) -> 26/8/2025 | I32: =IF(H32="","",Details!$F33) | J32: =IF(H32="","",Details!$E33) -> 30000 | K32: =IF(H32="","",K31+I32-J32) -> #REF!
A33: =IF(Settings!A34="","",Settings!A34) | B33: =IF($A33="","",SUMIF(Details!$C:$C,$A33,Details!$E:$E)) | C33: =IF($A33="","",IF(B33=0,"Not Started",IF(B33<#REF!,"In Progress","Completed"))) | H33: =IF(Details!$B35="","",Details!$B35) -> 26/8/2025 | I33: =IF(H33="","",Details!$F35) | J33: =IF(H33="","",Details!$E35) -> 15000 | K33: =IF(H33="","",K32+I33-J33) -> #REF!
A34: =IF(Settings!A35="","",Settings!A35) | B34: =IF($A34="","",SUMIF(Details!$C:$C,$A34,Details!$E:$E)) | C34: =IF($A34="","",IF(B34=0,"Not Started",IF(B34<#REF!,"In Progress","Completed"))) | H34: =IF(Details!$B37="","",Details!$B37) -> 28/8/2025 | I34: =IF(H34="","",Details!$F37) | J34: =IF(H34="","",Details!$E37) -> 22200 | K34: =IF(H34="","",K33+I34-J34) -> #REF!
A35: =IF(Settings!A36="","",Settings!A36) | B35: =IF($A35="","",SUMIF(Details!$C:$C,$A35,Details!$E:$E)) | C35: =IF($A35="","",IF(B35=0,"Not Started",IF(B35<#REF!,"In Progress","Completed"))) | H35: =IF(Details!$B38="","",Details!$B38) -> 28/8/2025 | I35: =IF(H35="","",Details!$F38) | J35: =IF(H35="","",Details!$E38) -> 6000 | K35: =IF(H35="","",K34+I35-J35) -> #REF!
A36: =IF(Settings!A37="","",Settings!A37) | B36: =IF($A36="","",SUMIF(Details!$C:$C,$A36,Details!$E:$E)) | C36: =IF($A36="","",IF(B36=0,"Not Started",IF(B36<#REF!,"In Progress","Completed"))) | H36: =IF(Details!$B39="","",Details!$B39) -> 28/8/2025 | I36: =IF(H36="","",Details!$F39) | J36: =IF(H36="","",Details!$E39) -> 3000 | K36: =IF(H36="","",K35+I36-J36) -> #REF!
A37: =IF(Settings!A38="","",Settings!A38) | B37: =IF($A37="","",SUMIF(Details!$C:$C,$A37,Details!$E:$E)) | C37: =IF($A37="","",IF(B37=0,"Not Started",IF(B37<#REF!,"In Progress","Completed"))) | H37: =IF(Details!$B40="","",Details!$B40) -> 28/8/2025 | I37: =IF(H37="","",Details!$F40) | J37: =IF(H37="","",Details!$E40) -> 5000 | K37: =IF(H37="","",K36+I37-J37) -> #REF!
A38: =IF(Settings!A39="","",Settings!A39) | B38: =IF($A38="","",SUMIF(Details!$C:$C,$A38,Details!$E:$E)) | C38: =IF($A38="","",IF(B38=0,"Not Started",IF(B38<#REF!,"In Progress","Completed"))) | H38: =IF(Details!$B41="","",Details!$B41) -> 28/8/2025 | I38: =IF(H38="","",Details!$F41) | J38: =IF(H38="","",Details!$E41) -> 1500 | K38: =IF(H38="","",K37+I38-J38) -> #REF!
A39: =IF(Settings!A40="","",Settings!A40) | B39: =IF($A39="","",SUMIF(Details!$C:$C,$A39,Details!$E:$E)) | C39: =IF($A39="","",IF(B39=0,"Not Started",IF(B39<#REF!,"In Progress","Completed"))) | H39: =IF(Details!$B42="","",Details!$B42) -> 29/8/2025 | I39: =IF(H39="","",Details!$F42) | J39: =IF(H39="","",Details!$E42) -> 3500 | K39: =IF(H39="","",K38+I39-J39) -> #REF!
A40: =IF(Settings!A41="","",Settings!A41) | B40: =IF($A40="","",SUMIF(Details!$C:$C,$A40,Details!$E:$E)) | C40: =IF($A40="","",IF(B40=0,"Not Started",IF(B40<#REF!,"In Progress","Completed"))) | H40: =IF(Details!$B43="","",Details!$B43) -> 29/8/2025 | I40: =IF(H40="","",Details!$F43) | J40: =IF(H40="","",Details!$E43) -> 15000 | K40: =IF(H40="","",K39+I40-J40) -> #REF!
A41: =IF(Settings!A42="","",Settings!A42) | B41: =IF($A41="","",SUMIF(Details!$C:$C,$A41,Details!$E:$E)) | C41: =IF($A41="","",IF(B41=0,"Not Started",IF(B41<#REF!,"In Progress","Completed"))) | H41: =IF(Details!$B44="","",Details!$B44) -> 29/8/2025 | I41: =IF(H41="","",Details!$F44) | J41: =IF(H41="","",Details!$E44) -> 3000 | K41: =IF(H41="","",K40+I41-J41) -> #REF!
A42: =IF(Settings!A43="","",Settings!A43) | B42: =IF($A42="","",SUMIF(Details!$C:$C,$A42,Details!$E:$E)) | C42: =IF($A42="","",IF(B42=0,"Not Started",IF(B42<#REF!,"In Progress","Completed"))) | H42: =IF(Details!$B45="","",Details!$B45) -> 29/8/2025 | I42: =IF(H42="","",Details!$F45) | J42: =IF(H42="","",Details!$E45) -> 3000 | K42: =IF(H42="","",K41+I42-J42) -> #REF!
A43: =IF(Settings!A44="","",Settings!A44) | B43: =IF($A43="","",SUMIF(Details!$C:$C,$A43,Details!$E:$E)) | C43: =IF($A43="","",IF(B43=0,"Not Started",IF(B43<#REF!,"In Progress","Completed"))) | H43: =IF(Details!$B46="","",Details!$B46) -> 29/8/2025 | I43: =IF(H43="","",Details!$F46) | J43: =IF(H43="","",Details!$E46) -> 51000 | K43: =IF(H43="","",K42+I43-J43) -> #REF!
...

Sheet Settings
A1: Section | B1: PaymentMethod | C1: Status | D1: CostType
A2: Site preparation | B2: Cash | C2: Not Started | D2: Material
A3: Land & Permits | B3: Bank Transfer | C3: In Progress | D3: Manpower
A4: Foundation | B4: Mobile Money | C4: Completed | D4: Other
A5: Structure / Walls | B5: Cheque | C5: Delayed | D5: cash in
A6: Roofing | D6: cash out
A7: Doors & Windows | D7: Repairing
A8: Electrical
A9: Plumbing
A10: Finishes (Interior)
A11: Finishes (Exterior)
A12: Landscaping
A13: Contingency
A14: Security
A15: money
A16: Transport
A17: withdrwal
